Workbook

Sheet FTA_Responses
A1: Timestamp | B1: Email Address | C1: Full Name | D1: Phone Number | E1: Gender | F1: Home Address | G1: Hw was overall service experience? | H1: How will you rate your WORSHIP experience? | I1: How will you rate your WORD experience? | J1: Any general feedback for us? | K1: Wo invited you to TS? | L1: Would you like to be a member of TSP? | M1: I consent that my data provided in this form can be used by the Standpoint Church as deemed appropriate | N1: Select the most convenient date for your one-on-one meeting with Pastor Phil | O1: FTA_ID | P1: Response_Year | Q1: Response_Month
A2: 46050.667 | B2: joshuaamanyene@gmail.com | C2: Amanyene Joshua | D2: 07065656041 | E2: Female | F2: 11 Gregory Effiong off ikot Ansa. | G2: 4 | H2: 4 | I2: 4 | J2: It was very impactful | K2: A friend | L2: Maybe later | M2: I agree | N2: Monday, February 2 | O2: =CONCATENATE(LEFT(C2, 1), RIGHT(D2, 6)) -> A656041 | P2: =IF(A2="","", IF( ISNUMBER(A2), YEAR(A2), YEAR( DATE( MID(A2,7,4), MID(A2,4,2), MID(A2,1,2) ) ) ) ) -> 2026 | Q2: =IF(A2="","",TEXT(A2,"mmm")) -> Jan
A3: 46050.669 | B3: israelisaiah100@gmail.com | C3: Israel Etim Isaiah | D3: 7063970745 | E3: Male | F3: Abak | G3: 4 | H3: 3 | I3: 3 | J3: Excellent | K3: A friend | L3: Maybe later | M3: I agree | N3: Monday, February 2 | O3: =CONCATENATE(LEFT(C3, 1), RIGHT(D3, 6)) -> I970745 | P3: =IF(A3="","", IF( ISNUMBER(A3), YEAR(A3), YEAR( DATE( MID(A3,7,4), MID(A3,4,2), MID(A3,1,2) ) ) ) ) -> 2026 | Q3: =IF(A3="","",TEXT(A3,"mmm")) -> Jan
A4: 46051.246 | B4: seyivictoria8@gmail.com | C4: victoria Adigun | D4: 08131046559 | E4: Female | F4: Osongama estate,uyo | G4: 5 | H4: 4 | I4: 4 | K4: Colleague | L4: Maybe later | M4: I agree | N4: Sunday, February 1 | O4: =CONCATENATE(LEFT(C4, 1), RIGHT(D4, 6)) -> v046559 | P4: =IF(A4="","", IF( ISNUMBER(A4), YEAR(A4), YEAR( DATE( MID(A4,7,4), MID(A4,4,2), MID(A4,1,2) ) ) ) ) -> 2026 | Q4: =IF(A4="","",TEXT(A4,"mmm")) -> Jan
A5: 46051.618 | B5: iyohounyime@gmail.co | C5: UNYIME VICTOR IYOHO | D5: 08065856125 | E5: Male | F5: 22 navy road calabar | G5: 5 | H5: 4 | I5: 5 | J5: Not at all | K5: A friend | L5: Maybe later | M5: I agree | N5: Monday, February 2 | O5: =CONCATENATE(LEFT(C5, 1), RIGHT(D5, 6)) -> U856125 | P5: =IF(A5="","", IF( ISNUMBER(A5), YEAR(A5), YEAR( DATE( MID(A5,7,4), MID(A5,4,2), MID(A5,1,2) ) ) ) ) -> 2026 | Q5: =IF(A5="","",TEXT(A5,"mmm")) -> Jan
A6: 46051.675 | B6: jamesokovu422@gmail.com | C6: Okovu, James Ushuasung | D6: +2349035355176 | E6: Male | F6: Basang, Obanliku | G6: 4 | H6: 4 | I6: 4 | K6: A friend | L6: Not yet | M6: I agree | N6: Sunday, February 1 | O6: =CONCATENATE(LEFT(C6, 1), RIGHT(D6, 6)) -> O355176 | P6: =IF(A6="","", IF( ISNUMBER(A6), YEAR(A6), YEAR( DATE( MID(A6,7,4), MID(A6,4,2), MID(A6,1,2) ) ) ) ) -> 2026 | Q6: =IF(A6="","",TEXT(A6,"mmm")) -> Jan
A7: 46051.779 | B7: Stellaakpan2000@gmail.com | C7: Stella Akpan | D7: 09033916736 | E7: Female | F7: Nmecha street | G7: 4 | H7: 4 | I7: 3 | J7: Nil | K7: A friend | L7: Maybe later | M7: I agree | N7: Tuesday, February 3 | O7: =CONCATENATE(LEFT(C7, 1), RIGHT(D7, 6)) -> S916736 | P7: =IF(A7="","", IF( ISNUMBER(A7), YEAR(A7), YEAR( DATE( MID(A7,7,4), MID(A7,4,2), MID(A7,1,2) ) ) ) ) -> 2026 | Q7: =IF(A7="","",TEXT(A7,"mmm")) -> Jan
A8: 46052.316 | B8: emmanuelajie59@gmail.com | C8: Emmanuel Ajie | D8: 08148565855 | E8: Male | F8: Asi abang street | G8: 4 | H8: 4 | I8: 4 | J8: It was great and amazing | K8: A friend | L8: Maybe later | M8: I agree | N8: Sunday, February 1 | O8: =CONCATENATE(LEFT(C8, 1), RIGHT(D8, 6)) -> E565855 | P8: =IF(A8="","", IF( ISNUMBER(A8), YEAR(A8), YEAR( DATE( MID(A8,7,4), MID(A8,4,2), MID(A8,1,2) ) ) ) ) -> 2026 | Q8: =IF(A8="","",TEXT(A8,"mmm")) -> Jan
A9: 46052.48 | B9: nsimaemmanuel1999@gmail.com | C9: Timothy Emmanuel | D9: 09064303085 | E9: Male | F9: 8, Ajayi Street, Ketu, Lagos. | G9: 5 | H9: 5 | I9: 5 | J9: No | K9: A friend | L9: Not yet | M9: I agree | N9: Sunday, February 1 | O9: =CONCATENATE(LEFT(C9, 1), RIGHT(D9, 6)) -> T303085 | P9: =IF(A9="","", IF( ISNUMBER(A9), YEAR(A9), YEAR( DATE( MID(A9,7,4), MID(A9,4,2), MID(A9,1,2) ) ) ) ) -> 2026 | Q9: =IF(A9="","",TEXT(A9,"mmm")) -> Jan
A10: 46052.722 | B10: Oraclfrancis12@gmail.com | C10: Francis Ekanem Francis | D10: 8052718567 | E10: Male | F10: Nwaniba | G10: 5 | H10: 5 | I10: 5 | J10: Very good | K10: A worker in the church | L10: Maybe later | M10: I agree | N10: Tuesday, February 3 | O10: =CONCATENATE(LEFT(C10, 1), RIGHT(D10, 6)) -> F718567 | P10: =IF(A10="","", IF( ISNUMBER(A10), YEAR(A10), YEAR( DATE( MID(A10,7,4), MID(A10,4,2), MID(A10,1,2) ) ) ) ) -> 2026 | Q10: =IF(A10="","",TEXT(A10,"mmm")) -> Jan
A11: 46052.834 | B11: clarapatience68@gmail.com | C11: SUNDAY CLARA IME | D11: +2348077175611 | E11: Female | F11: 302 Artillery Regiment barracks, Onitsha | G11: 5 | H11: 5 | I11: 5 | K11: Church member | L11: Yes | M11: I agree | N11: Wednesday, February 4 | O11: =CONCATENATE(LEFT(C11, 1), RIGHT(D11, 6)) -> S175611 | P11: =IF(A11="","", IF( ISNUMBER(A11), YEAR(A11), YEAR( DATE( MID(A11,7,4), MID(A11,4,2), MID(A11,1,2) ) ) ) ) -> 2026 | Q11: =IF(A11="","",TEXT(A11,"mmm")) -> Jan
A12: 46053.381 | B12: felicitandifon@gmail.com | C12: Felicita Okon Ndifon | D12: 8116883482 | E12: Female | F12: 10 ikot ansa street calabar | G12: 5 | H12: 5 | I12: 5 | K12: A friend | L12: Not yet | M12: I agree | N12: Wednesday, February 4 | O12: =CONCATENATE(LEFT(C12, 1), RIGHT(D12, 6)) -> F883482 | P12: =IF(A12="","", IF( ISNUMBER(A12), YEAR(A12), YEAR( DATE( MID(A12,7,4), MID(A12,4,2), MID(A12,1,2) ) ) ) ) -> 2026 | Q12: =IF(A12="","",TEXT(A12,"mmm")) -> Jan
A13: 46053.382 | B13: ajiejosephsimon@gmail.com | C13: Joseph Simon ajie | D13: 09067506636 | E13: Male | F13: #no2 asi abang street | G13: 3 | H13: 3 | I13: 4 | K13: A friend | L13: Yes | M13: I agree | N13: Wednesday, February 4 | O13: =CONCATENATE(LEFT(C13, 1), RIGHT(D13, 6)) -> J506636 | P13: =IF(A13="","", IF( ISNUMBER(A13), YEAR(A13), YEAR( DATE( MID(A13,7,4), MID(A13,4,2), MID(A13,1,2) ) ) ) ) -> 2026 | Q13: =IF(A13="","",TEXT(A13,"mmm")) -> Jan
A14: 46053.418 | B14: akpangodswillprof3@gmail.com | C14: Akpan Godswill Archibong | D14: 07026820431 | E14: Male | F14: 7 etok ekpat street, uyo, Akwa ibom state | G14: 4 | H14: 4 | I14: 4 | J14: All things were excellent | K14: A friend | L14: Yes | M14: I agree | N14: Sunday, February 1 | O14: =CONCATENATE(LEFT(C14, 1), RIGHT(D14, 6)) -> A820431 | P14: =IF(A14="","", IF( ISNUMBER(A14), YEAR(A14), YEAR( DATE( MID(A14,7,4), MID(A14,4,2), MID(A14,1,2) ) ) ) ) -> 2026 | Q14: =IF(A14="","",TEXT(A14,"mmm")) -> Jan
A15: 46053.428 | B15: honestyakpanim@gmail.com | C15: Honesty Etim Akpanim | D15: 09167082308 | E15: Male | F15: Use offot nwaniba road | G15: 5 | H15: 5 | I15: 5 | K15: Colleague | L15: Yes | M15: I agree | N15: Sunday, February 1 | O15: =CONCATENATE(LEFT(C15, 1), RIGHT(D15, 6)) -> H082308 | P15: =IF(A15="","", IF( ISNUMBER(A15), YEAR(A15), YEAR( DATE( MID(A15,7,4), MID(A15,4,2), MID(A15,1,2) ) ) ) ) -> 2026 | Q15: =IF(A15="","",TEXT(A15,"mmm")) -> Jan
A16: 46053.45 | B16: Innocent16082006@gmail.com | C16: Okereke Innocent | D16: 09129711171 | E16: Male | F16: Ebonyi state | G16: 5 | H16: 5 | I16: 5 | K16: A friend | L16: Maybe later | M16: I agree | N16: Sunday, February 1 | O16: =CONCATENATE(LEFT(C16, 1), RIGHT(D16, 6)) -> O711171 | P16: =IF(A16="","", IF( ISNUMBER(A16), YEAR(A16), YEAR( DATE( MID(A16,7,4), MID(A16,4,2), MID(A16,1,2) ) ) ) ) -> 2026 | Q16: =IF(A16="","",TEXT(A16,"mmm")) -> Jan
A17: 46053.455 | B17: estherbaseey209@gmail.com | C17: Bassey Courage Ike | D17: 7070788605 | E17: Female | F17: No 4 Ikot Abasi Obori | G17: 5 | H17: 5 | I17: 3 | J17: No | K17: A friend | L17: Not yet | M17: I agree | N17: Wednesday, February 4 | O17: =CONCATENATE(LEFT(C17, 1), RIGHT(D17, 6)) -> B788605 | P17: =IF(A17="","", IF( ISNUMBER(A17), YEAR(A17), YEAR( DATE( MID(A17,7,4), MID(A17,4,2), MID(A17,1,2) ) ) ) ) -> 2026 | Q17: =IF(A17="","",TEXT(A17,"mmm")) -> Jan
A18: 46053.458 | B18: nteteasuquo@gmail.com | C18: Ntete Ita Asuquo | D18: 08132105266 | E18: Male | F18: No 2b Ikot Esu diamond hill Calabar | G18: 5 | H18: 5 | I18: 5 | K18: A friend | L18: Not yet | M18: I agree | N18: Wednesday, February 4 | O18: =CONCATENATE(LEFT(C18, 1), RIGHT(D18, 6)) -> N105266 | P18: =IF(A18="","", IF( ISNUMBER(A18), YEAR(A18), YEAR( DATE( MID(A18,7,4), MID(A18,4,2), MID(A18,1,2) ) ) ) ) -> 2026 | Q18: =IF(A18="","",TEXT(A18,"mmm")) -> Jan
A19: 46053.465 | B19: cliffordetuk@gmail.com | C19: Clifford | D19: 09095043405 | E19: Male | F19: Elikpokwudu, Rupkokwu | G19: 3 | H19: 3 | I19: 3 | J19: No | K19: Other | L19: Not yet | M19: I agree | N19: Wednesday, February 4 | O19: =CONCATENATE(LEFT(C19, 1), RIGHT(D19, 6)) -> C043405 | P19: =IF(A19="","", IF( ISNUMBER(A19), YEAR(A19), YEAR( DATE( MID(A19,7,4), MID(A19,4,2), MID(A19,1,2) ) ) ) ) -> 2026 | Q19: =IF(A19="","",TEXT(A19,"mmm")) -> Jan
A20: 46053.49 | B20: workkiro05@gmail.com | C20: Stephen Inah | D20: 09015038171 | E20: Male | F20: Ghjk | G20: 1 | H20: 1 | I20: 3 | K20: A friend | L20: Not yet | M20: I agree | N20: Sunday, February 1 | O20: =CONCATENATE(LEFT(C20, 1), RIGHT(D20, 6)) -> S038171 | P20: =IF(A20="","", IF( ISNUMBER(A20), YEAR(A20), YEAR( DATE( MID(A20,7,4), MID(A20,4,2), MID(A20,1,2) ) ) ) ) -> 2026 | Q20: =IF(A20="","",TEXT(A20,"mmm")) -> Jan
A21: 46053.51 | B21: samuelogbade@gmail.com | C21: Samuel nduka onuegbu | D21: 07064334327 | E21: Male | F21: 72 essien town | G21: 5 | H21: 4 | I21: 3 | K21: A friend | L21: Yes | M21: I agree | N21: Wednesday, February 4 | O21: =CONCATENATE(LEFT(C21, 1), RIGHT(D21, 6)) -> S334327 | P21: =IF(A21="","", IF( ISNUMBER(A21), YEAR(A21), YEAR( DATE( MID(A21,7,4), MID(A21,4,2), MID(A21,1,2) ) ) ) ) -> 2026 | Q21: =IF(A21="","",TEXT(A21,"mmm")) -> Jan
A22: 46053.513 | B22: aquamanzy677@gmail.com | C22: Effiong, Bassey Bassey | D22: 08137834265 | E22: Male | F22: Mega Hilton, Aluu | G22: 5 | H22: 5 | I22: 5 | K22: A friend | L22: Not yet | M22: I agree | N22: Wednesday, February 4 | O22: =CONCATENATE(LEFT(C22, 1), RIGHT(D22, 6)) -> E834265 | P22: =IF(A22="","", IF( ISNUMBER(A22), YEAR(A22), YEAR( DATE( MID(A22,7,4), MID(A22,4,2), MID(A22,1,2) ) ) ) ) -> 2026 | Q22: =IF(A22="","",TEXT(A22,"mmm")) -> Jan
A23: 46053.532 | B23: inipatience60@gmail.com | C23: Patience Asuquo | D23: +234-7044070453 | E23: Female | F23: Mcc road | G23: 4 | H23: 4 | I23: 4 | J23: Best | K23: A friend | L23: Not yet | M23: I agree | N23: Monday, February 2 | O23: =CONCATENATE(LEFT(C23, 1), RIGHT(D23, 6)) -> P070453 | P23: =IF(A23="","", IF( ISNUMBER(A23), YEAR(A23), YEAR( DATE( MID(A23,7,4), MID(A23,4,2), MID(A23,1,2) ) ) ) ) -> 2026 | Q23: =IF(A23="","",TEXT(A23,"mmm")) -> Jan
A24: 46053.574 | B24: isaiahisrael@gmail com | C24: Israel Isaiah | D24: 09125988364 | E24: Male | F24: Nwaniba | G24: 4 | H24: 4 | I24: 4 | K24: A friend | L24: Not yet | M24: I agree | N24: Sunday, February 1 | O24: =CONCATENATE(LEFT(C24, 1), RIGHT(D24, 6)) -> I988364 | P24: =IF(A24="","", IF( ISNUMBER(A24), YEAR(A24), YEAR( DATE( MID(A24,7,4), MID(A24,4,2), MID(A24,1,2) ) ) ) ) -> 2026 | Q24: =IF(A24="","",TEXT(A24,"mmm")) -> Jan
A25: 46053.615 | B25: kamadaniel978@gmail.com | C25: DANIEL LEDOGO KAMA | D25: 07035328175 | E25: Male | F25: 170 old refinery old, Elelenwo portharcourt | G25: 3 | H25: 4 | I25: 4 | J25: Please improve on your services | K25: Colleague | L25: Maybe later | M25: I agree | N25: Wednesday, February 4 | O25: =CONCATENATE(LEFT(C25, 1), RIGHT(D25, 6)) -> D328175 | P25: =IF(A25="","", IF( ISNUMBER(A25), YEAR(A25), YEAR( DATE( MID(A25,7,4), MID(A25,4,2), MID(A25,1,2) ) ) ) ) -> 2026 | Q25: =IF(A25="","",TEXT(A25,"mmm")) -> Jan
A26: 46053.624 | B26: betabasiudo@gmail.com | C26: Bet-Abasi Monday Udo | D26: 07033550180 | E26: Male | F26: Ikot Effiok St Useofot | G26: 5 | H26: 3 | I26: 4 | K26: A worker in the church | L26: Yes | M26: I agree | N26: Sunday, February 1 | O26: =CONCATENATE(LEFT(C26, 1), RIGHT(D26, 6)) -> B550180 | P26: =IF(A26="","", IF( ISNUMBER(A26), YEAR(A26), YEAR( DATE( MID(A26,7,4), MID(A26,4,2), MID(A26,1,2) ) ) ) ) -> 2026 | Q26: =IF(A26="","",TEXT(A26,"mmm")) -> Jan
A27: 46054.869 | B27: blessingakpanokon25@gmail.com | C27: Blessing okon Akpan | D27: 08160289390 | E27: Female | F27: No 28 idak edat street uyo | G27: 4 | H27: 3 | I27: 2 | J27: We should keep pushing God's work forward | K27: A friend | L27: Not yet | M27: I agree | N27: Wednesday, February 4 | O27: =CONCATENATE(LEFT(C27, 1), RIGHT(D27, 6)) -> B289390 | P27: =IF(A27="","", IF( ISNUMBER(A27), YEAR(A27), YEAR( DATE( MID(A27,7,4), MID(A27,4,2), MID(A27,1,2) ) ) ) ) -> 2026 | Q27: =IF(A27="","",TEXT(A27,"mmm")) -> Feb
A28: 46055.462 | B28: elizabethabimbola200@gmail.com | C28: Elizabeth Gabriel Abimbola | D28: 09115314204 | E28: Female | F28: Akpasak estate | G28: 5 | H28: 4 | I28: 4 | K28: A friend | L28: Not yet | M28: I agree | N28: Wednesday, February 4 | O28: =CONCATENATE(LEFT(C28, 1), RIGHT(D28, 6)) -> E314204 | P28: =IF(A28="","", IF( ISNUMBER(A28), YEAR(A28), YEAR( DATE( MID(A28,7,4), MID(A28,4,2), MID(A28,1,2) ) ) ) ) -> 2026 | Q28: =IF(A28="","",TEXT(A28,"mmm")) -> Feb
A29: 46056.996 | B29: test01@email.com | C29: Sylva Donatus | D29: +2348067676843 | E29: Male | F29: 4 Controller street | G29: 4 | H29: 5 | I29: 4 | J29: I will like to visit again | K29: A friend | L29: Not yet | M29: I agree | N29: Wednesday, February 4 | O29: =CONCATENATE(LEFT(C29, 1), RIGHT(D29, 6)) -> S676843 | P29: =IF(A29="","", IF( ISNUMBER(A29), YEAR(A29), YEAR( DATE( MID(A29,7,4), MID(A29,4,2), MID(A29,1,2) ) ) ) ) -> 2026 | Q29: =IF(A29="","",TEXT(A29,"mmm")) -> Feb
A30: 46057.014 | B30: test02@email.com | C30: Rejoice Samuel | D30: 07045624536 | E30: Female | F30: 4 Union Road | G30: 3 | H30: 4 | I30: 4 | J30: A good time in His presence | K30: Self(social Media) | L30: Maybe later | M30: I agree | N30: Wednesday, February 4 | O30: =CONCATENATE(LEFT(C30, 1), RIGHT(D30, 6)) -> R624536 | P30: =IF(A30="","", IF( ISNUMBER(A30), YEAR(A30), YEAR( DATE( MID(A30,7,4), MID(A30,4,2), MID(A30,1,2) ) ) ) ) -> 2026 | Q30: =IF(A30="","",TEXT(A30,"mmm")) -> Feb
A31: 46057.016 | B31: test03@email.com | C31: Larry Galadim | D31: 09032225556 | E31: Male | F31: willington Way | G31: 4 | H31: 3 | I31: 5 | J31: Sweet service | K31: A friend | L31: Yes | M31: I agree | N31: Tuesday, February 3 | O31: =CONCATENATE(LEFT(C31, 1), RIGHT(D31, 6)) -> L225556 | P31: =IF(A31="","", IF( ISNUMBER(A31), YEAR(A31), YEAR( DATE( MID(A31,7,4), MID(A31,4,2), MID(A31,1,2) ) ) ) ) -> 2026 | Q31: =IF(A31="","",TEXT(A31,"mmm")) -> Feb
A32: 46057.02 | B32: test02@email.com | C32: Belammy Joel | D32: +234-456-678-999 | E32: Male | F32: 6 Office Road, Uyo | G32: 5 | H32: 5 | I32: 4 | J32: Joy in Praising God | K32: A worker in the church | L32: Yes | M32: I agree | N32: Wednesday, February 4 | O32: =CONCATENATE(LEFT(C32, 1), RIGHT(D32, 6)) -> B78-999 | P32: =IF(A32="","", IF( ISNUMBER(A32), YEAR(A32), YEAR( DATE( MID(A32,7,4), MID(A32,4,2), MID(A32,1,2) ) ) ) ) -> 2026 | Q32: =IF(A32="","",TEXT(A32,"mmm")) -> Feb
A33: 46057.025 | B33: test05@email.com | C33: Caroline James | D33: 09078786512 | E33: Female | F33: 55 Babcck Avenue | G33: 4 | H33: 3 | I33: 4 | J33: I enjoyed my stay | K33: Self(Billboard) | L33: Yes | M33: I agree | N33: Wednesday, February 4 | O33: =CONCATENATE(LEFT(C33, 1), RIGHT(D33, 6)) -> C786512 | P33: =IF(A33="","", IF( ISNUMBER(A33), YEAR(A33), YEAR( DATE( MID(A33,7,4), MID(A33,4,2), MID(A33,1,2) ) ) ) ) -> 2026 | Q33: =IF(A33="","",TEXT(A33,"mmm")) -> Feb
A34: 46057.027 | B34: test06@email.com | C34: Itoro Nkereuwem | D34: 07044445577 | E34: Male | F34: Oron Road by Crunches | G34: 5 | H34: 5 | I34: 4 | J34: I felt the presence of God | K34: Church member | L34: Maybe later | M34: I agree | N34: Wednesday, February 4 | O34: =CONCATENATE(LEFT(C34, 1), RIGHT(D34, 6)) -> I445577 | P34: =IF(A34="","", IF( ISNUMBER(A34), YEAR(A34), YEAR( DATE( MID(A34,7,4), MID(A34,4,2), MID(A34,1,2) ) ) ) ) -> 2026 | Q34: =IF(A34="","",TEXT(A34,"mmm")) -> Feb
A35: 46057.03 | B35: test07@email.com | C35: Angelina Johnathan | D35: 08045327711 | E35: Female | F35: 6 Atamunu by Jebs street | G35: 3 | H35: 4 | I35: 4 | J35: I felt the power of Jesus | K35: A friend | L35: Not yet | M35: I agree | N35: Wednesday, February 4 | O35: =CONCATENATE(LEFT(C35, 1), RIGHT(D35, 6)) -> A327711 | P35: =IF(A35="","", IF( ISNUMBER(A35), YEAR(A35), YEAR( DATE( MID(A35,7,4), MID(A35,4,2), MID(A35,1,2) ) ) ) ) -> 2026 | Q35: =IF(A35="","",TEXT(A35,"mmm")) -> Feb
A36: 46057.033 | B36: test08@email.com | C36: Ebong John | D36: 09063333330 | E36: Male | F36: Federal Housing, Plot 6F | G36: 4 | H36: 5 | I36: 4 | J36: Great service | K36: A worker in the church | L36: Yes | M36: I agree | N36: Wednesday, February 4 | O36: =CONCATENATE(LEFT(C36, 1), RIGHT(D36, 6)) -> E333330 | P36: =IF(A36="","", IF( ISNUMBER(A36), YEAR(A36), YEAR( DATE( MID(A36,7,4), MID(A36,4,2), MID(A36,1,2) ) ) ) ) -> 2026 | Q36: =IF(A36="","",TEXT(A36,"mmm")) -> Feb
A37: 46057.035 | B37: test09@email.com | C37: Young Philips | D37: 09045432110 | E37: Male | F37: Gateway road, Onitsha | G37: 4 | H37: 4 | I37: 5 | J37: The reception was great | K37: Church member | L37: Yes | M37: I agree | N37: Wednesday, February 4 | O37: =CONCATENATE(LEFT(C37, 1), RIGHT(D37, 6)) -> Y432110 | P37: =IF(A37="","", IF( ISNUMBER(A37), YEAR(A37), YEAR( DATE( MID(A37,7,4), MID(A37,4,2), MID(A37,1,2) ) ) ) ) -> 2026 | Q37: =IF(A37="","",TEXT(A37,"mmm")) -> Feb
A38: 46057.037 | B38: test10@email.com | C38: Eunice Everest | D38: 08067676780 | E38: Female | F38: Assembly Quarters | G38: 4 | H38: 5 | I38: 5 | J38: The sound system is very good | K38: Spouse | L38: Not yet | M38: I agree | N38: Wednesday, February 4 | O38: =CONCATENATE(LEFT(C38, 1), RIGHT(D38, 6)) -> E676780 | P38: =IF(A38="","", IF( ISNUMBER(A38), YEAR(A38), YEAR( DATE( MID(A38,7,4), MID(A38,4,2), MID(A38,1,2) ) ) ) ) -> 2026 | Q38: =IF(A38="","",TEXT(A38,"mmm")) -> Feb
A39: 46058.686 | B39: nnamdi@datafiedtech.com | C39: Austin Wealth | D39: +2347013623317 | E39: Male | F39: 5 B14 Street Citec Estate Mbora | G39: 5 | H39: 4 | I39: 5 | J39: Nil | K39: A friend | L39: Yes | M39: I agree | N39: Monday, February 2 | O39: =CONCATENATE(LEFT(C39, 1), RIGHT(D39, 6)) -> A623317 | P39: =IF(A39="","", IF( ISNUMBER(A39), YEAR(A39), YEAR( DATE( MID(A39,7,4), MID(A39,4,2), MID(A39,1,2) ) ) ) ) -> 2026 | Q39: =IF(A39="","",TEXT(A39,"mmm")) -> Feb

Sheet Feedback_Responses
A1: Timestamp | B1: FTA_ID | C1: A-Team Member | D1: FTA Call | E1: Called | F1: Feedback | G1: M&G confirmation Date_on_1st_call | H1: General feedback_on_1st_call | I1: Choose the date you met your FTA | J1: General feedback_on_2nd_call | K1: General feedback_on_3rd_call | L1: Date_on_M & G_confirmation_call | M1: Feedback_on_M&G_confirmation_call
A2: 46057.088 | B2: S676843 | C2: Sandy Rose | D2: 1st call (Actual contact) | E2: Yes | F2: Out of town | G2: Wednesday, February 4 | H2: FTA appreciated the call and promised to visit the church again.
A3: 46057.341 | B3: R624536 | C3: Ama Joshua | D3: 1st call (Actual contact) | E3: Yes, sent TSP communique | F3: Prayer request | G3: Wednesday, February 4 | H3: Call to FTA was successful, she promised that she may come back
A4: 46057.346 | B4: L225556 | C4: Henry Jacob | D4: 1st call (Actual contact) | E4: Yes | F4: Would love to join | G4: Tuesday. February 3 | H4: FTA Admitted that it was a nice time in God's presence
A5: 46057.349 | B5: C786512 | C5: Emmanuel Ita | D5: 1st call (Actual contact) | E5: Yes | F5: Hope to visit again | G5: Wednesday, February 4 | H5: FTA confessed she enjoyed the service
A6: 46057.351 | B6: I445577 | C6: Tombere Regina | D6: 1st call (Actual contact) | E6: Yes | F6: Would love to join | G6: Wednesday, February 4 | H6: FTA received the call with Joy. She admitted feeling the presence of God
A7: 46057.361 | B7: A327711 | C7: Bassey Esther | D7: 1st call (Actual contact) | E7: Yes | F7: Just visiting | G7: Wednesday, February 4 | H7: FTA appreciated the call. She promised to return
A8: 46057.364 | B8: E333330 | C8: Elijah Effiong | D8: 1st call (Actual contact) | E8: Yes | F8: Hope to visit again | G8: Wednesday, February 4 | H8: Feedback from FTA about service was generally impressive.

Sheet Assignment_Log
A1: Timestamp | B1: FTA_ID | C1: FTA_Name | D1: FTA_Email | E1: Assigned_Member_ID | F1: Assigned_Member_Name | G1: Assigned_Member_Email | H1: Status | I1: Note | J1: Response_Time_Hours
A2: 46051.618 | B2: U856125 | C2: UNYIME VICTOR IYOHO | D2: iyohounyime@gmail.co | E2: B004 | F2: Emmanuel Ita | G2: emmanuelita93@gmail.com | H2: Assigned | J2: 83.21
A3: 46051.675 | B3: O355176 | C3: Okovu, James Ushuasung | D3: jamesokovu422@gmail.com | E3: B005 | F3: Tombere Regina | G3: tomberereginajoseph@gmail.com | H3: Assigned | J3: 81.84
A4: 46051.779 | B4: S916736 | C4: Stella Akpan | D4: Stellaakpan2000@gmail.com | E4: B006 | F4: Sandy Rose | G4: rossycluster@gmail.com | H4: Assigned | J4: 79.36
A5: 46052.316 | B5: E565855 | C5: Emmanuel Ajie | D5: emmanuelajie59@gmail.com | E5: B007 | F5: Bassey Esther | G5: estybl95@gmail.com | H5: Assigned | J5: 66.45
A6: 46052.48 | B6: T303085 | C6: Timothy Emmanuel | D6: nsimaemmanuel1999@gmail.com | E6: B008 | F6: Elijah Effiong | G6: elijaheffiongsam@gmail.com | H6: Assigned | J6: 62.53
A7: 46052.722 | B7: F718567 | C7: Francis Ekanem Francis | D7: Oraclfrancis12@gmail.com | E7: B009 | F7: Ubong Anuak | G7: ubonganuak56@gmail.com | H7: Assigned | J7: 56.72
A8: 46052.834 | B8: S175611 | C8: SUNDAY CLARA IME | D8: clarapatience68@gmail.com | E8: B010 | F8: Precious Effiong | G8: peffiong678@gmail.com | H8: Assigned | J8: 54.02
A9: 46053.381 | B9: F883482 | C9: Felicita Okon Ndifon | D9: felicitandifon@gmail.com | E9: B011 | F9: Idara Nnah | G9: nnahidara966@gmail.com | H9: Assigned | J9: 40.89
A10: 46053.382 | B10: J506636 | C10: Joseph Simon ajie | D10: ajiejosephsimon@gmail.com | E10: B012 | F10: Iniobong William | G10: inbowilliams@gmail.com | H10: Assigned | J10: 40.88
A11: 46053.418 | B11: A820431 | C11: Akpan Godswill Archibong | D11: akpangodswillprof3@gmail.com | E11: B001 | F11: Ama Joshua | G11: joshuaamanyene@gmail.com | H11: Assigned | J11: 40.02
A12: 46053.428 | B12: H082308 | C12: Honesty Etim Akpanim | D12: honestyakpanim@gmail.com | E12: B002 | F12: Wisdom Ekpenyong | G12: wizzyekpenyong@gmail.com | H12: Assigned | J12: 39.77
A13: 46053.45 | B13: O711171 | C13: Okereke Innocent | D13: Innocent16082006@gmail.com | E13: B003 | F13: Henry Jacob | G13: henro360@gmail.com | H13: Assigned | J13: 39.23
... A37: 46058.686 | B37: A623317 | C37: Austin Wealth | D37: nnamdi@datafiedtech.com | E37: B009 | F37: Ubong Anuak | G37: ubonganuak56@gmail.com | H37: Assigned | J37: 14.52

Sheet A-Team_Members
A1: Member_ID | B1: Full_Name | C1: Email | D1: Phone | E1: Max_capacity | F1: Current_Load | G1: Status
A2: B001 | B2: Ama Joshua | C2: joshuaamanyene@gmail.com | D2: 7065656041 | E2: 5 | F2: 4 | G2: Active
A3: B002 | B3: Wisdom Ekpenyong | C3: wizzyekpenyong@gmail.com | D3: 8068101622 | E3: 5 | F3: 4 | G3: Active
A4: B003 | B4: Henry Jacob | C4: henro360@gmail.com | D4: 8039114028 | E4: 5 | F4: 4 | G4: Active
A5: B004 | B5: Emmanuel Ita | C5: emmanuelita93@gmail.com | D5: 7062130531 | E5: 5 | F5: 4 | G5: Active
A6: B005 | B6: Tombere Regina | C6: tomberereginajoseph@gmail.com | D6: 9025137360 | E6: 5 | F6: 4 | G6: Active
A7: B006 | B7: Sandy Rose | C7: rossycluster@gmail.com | D7: 9133203309 | E7: 5 | F7: 4 | G7: Active
A8: B007 | B8: Bassey Esther | C8: estybl95@gmail.com | D8: 9031582189 | E8: 5 | F8: 4 | G8: Active
A9: B008 | B9: Elijah Effiong | C9: elijaheffiongsam@gmail.com | D9: 8081079642 | E9: 5 | F9: 4 | G9: Active
A10: B009 | B10: Ubong Anuak | C10: ubonganuak56@gmail.com | D10: 8023322989 | E10: 5 | F10: 4 | G10: Active
A11: B010 | B11: Precious Effiong | C11: peffiong678@gmail.com | D11: 8130891137 | E11: 5 | F11: 3 | G11: Active
A12: B011 | B12: Idara Nnah | C12: nnahidara966@gmail.com | D12: 8030554007 | E12: 5 | F12: 3 | G12: Active
A13: B012 | B13: Iniobong William | C13: inbowilliams@gmail.com | D13: 7032593600 | E13: 5 | F13: 3 | G13: Active

Sheet Dashboard_Metrics
A1: METRIC | B1: FORMULA
A2: Total FTAs (All-time) | B2: =COUNTA(FTA_Responses!O:O)-1 -> 38
A3: FTAs This Month | B3: =COUNTIFS(FTA_Responses!A:A,">="&EOMONTH(TODAY(),-1)+1, FTA_Responses!A:A,"<="&EOMONTH(TODAY(),0)) -> 0
A4: FTAs This Week | B4: =COUNTIFS(FTA_Responses!A:A,">="&TODAY()-WEEKDAY(TODAY(),2)+1, FTA_Responses!A:A,"<="&TODAY()-WEEKDAY(TODAY(),2)+7) -> 0
A5: FTAs Today | B5: {=COUNTIF(INT(FTA_Responses!A2:A1000), TODAY())} -> 0
A6: Average Overall Experience Rating | B6: =AVERAGE(FTA_Responses!G:G) -> 4.2368421
A7: Average Worship Rating | B7: =AVERAGE(FTA_Responses!H:H) -> 4.1052632
A8: Average Word Rating | B8: =AVERAGE(FTA_Responses!I:I) -> 4.1315789
A9: Membership Interest Rate (%) | B9: =COUNTIF(FTA_Responses!L:L,"Yes") / (COUNTA(FTA_Responses!O:O)-1)*100 -> 31.578947
A10: Follow-up Completion Rate (%) | B10: =COUNTIF(Assignment_Log!H:H,"Assigned")/COUNTA(FTA_Responses!O:O)*100 -> 92.307692
A20: FTA Source Analysis Table.
A21: SOURCE | B21: COUNT | C21: % of TOTAL
A22: A friend | B22: =COUNTIF(FTA_Responses!K:K,"A friend") -> 24 | C22: =B22 / COUNTA(FTA_Responses!O:O) -> 0.61538462
A23: A worker in the church | B23: =COUNTIF(FTA_Responses!K:K,"A worker in the church") -> 4 | C23: =B23 / COUNTA(FTA_Responses!O:O) -> 0.1025641
A24: Church member | B24: =COUNTIF(FTA_Responses!K:K,"Church member") -> 3 | C24: =B24 / COUNTA(FTA_Responses!O:O) -> 0.076923077
A25: Colleague | B25: =COUNTIF(FTA_Responses!K:K,"Colleague") -> 3 | C25: =B25 / COUNTA(FTA_Responses!O:O) -> 0.076923077
A26: Spouse | B26: =COUNTIF(FTA_Responses!K:K,"Spouse") -> 1 | C26: =B26 / COUNTA(FTA_Responses!O:O) -> 0.025641026
A27: Self (Social Media) | B27: =COUNTIF(FTA_Responses!K:K,"Self(Social Media)") -> 1 | C27: =B27 / COUNTA(FTA_Responses!O:O) -> 0.025641026
A28: Self (Billboard) | B28: =COUNTIF(FTA_Responses!K:K,"Self(Billboard)") -> 1 | C28: =B28 / COUNTA(FTA_Responses!O:O) -> 0.025641026
A29: Home cell | B29: =COUNTIF(FTA_Responses!K:K,"Home cell") -> 0 | C29: =B29 / COUNTA(FTA_Responses!O:O) -> 0
A30: Other | B30: =COUNTIF(FTA_Responses!K:K,"Other") -> 1 | C30: =B30 / COUNTA(FTA_Responses!O:O) -> 0.025641026
A33: A -Team Performance Table
A34: TEAM MEMBER | B34: ASSIGNMENT | C34: AVG OVERALL RATING
A35: Henry Jacob | B35: =COUNTIF(Assignment_Log!F:F, A35) -> 3 | C35: =AVERAGEIF(Assignment_Log!F:F, A35, FTA_Responses!G:G) -> 3.3333333
A36: Ama Joshua | B36: =COUNTIF(Assignment_Log!F:F, A36) -> 3 | C36: =AVERAGEIF(Assignment_Log!F:F, A36, FTA_Responses!G:G) -> 4
A37: Wisdom Ekpenyong | B37: =COUNTIF(Assignment_Log!F:F, A37) -> 2 | C37: =AVERAGEIF(Assignment_Log!F:F, A37, FTA_Responses!G:G) -> 4.5
A38: Emmanuel Ita | B38: =COUNTIF(Assignment_Log!F:F, A38) -> 3 | C38: =AVERAGEIF(Assignment_Log!F:F, A38, FTA_Responses!G:G) -> 4.3333333
A39: Tombere Regina | B39: =COUNTIF(Assignment_Log!F:F, A39) -> 3 | C39: =AVERAGEIF(Assignment_Log!F:F, A39, FTA_Responses!G:G) -> 4.3333333
A40: Sandy Rose | B40: =COUNTIF(Assignment_Log!F:F, A40) -> 3 | C40: =AVERAGEIF(Assignment_Log!F:F, A40, FTA_Responses!G:G) -> 5
A41: Bassey Esther | B41: =COUNTIF(Assignment_Log!F:F, A41) -> 3 | C41: =AVERAGEIF(Assignment_Log!F:F, A41, FTA_Responses!G:G) -> 4.6666667
A42: Elijah Effiong | B42: =COUNTIF(Assignment_Log!F:F, A42) -> 3 | C42: =AVERAGEIF(Assignment_Log!F:F, A42, FTA_Responses!G:G) -> 4
A43: Ubong Anuak | B43: =COUNTIF(Assignment_Log!F:F, A43) -> 4 | C43: =AVERAGEIF(Assignment_Log!F:F, A43, FTA_Responses!G:G) -> 3.75
A44: Precious Effiong | B44: =COUNTIF(Assignment_Log!F:F, A44) -> 3 | C44: =AVERAGEIF(Assignment_Log!F:F, A44, FTA_Responses!G:G) -> 3.3333333
A50: Monthly Trend Data.
A51: MONTH | B51: COUNT OF FTAs
A52: 46023 | B52: =COUNTIFS( FTA_Responses!$A:$A, ">=" & DATE(YEAR($A52), MONTH($A52), 1), FTA_Responses!$A:$A, "<" & EOMONTH(DATE(YEAR($A52), MONTH($A52), 1), 0) + 1 ) -> 25
A53: =EDATE(A52,1) -> 46054 | B53: =COUNTIFS( FTA_Responses!$A:$A, ">=" & DATE(YEAR($A53), MONTH($A53), 1), FTA_Responses!$A:$A, "<" & EOMONTH(DATE(YEAR($A53), MONTH($A53), 1), 0) + 1 ) -> 13
A54: =EDATE(A53,1) -> 46082 | B54: =COUNTIFS( FTA_Responses!$A:$A, ">=" & DATE(YEAR($A54), MONTH($A54), 1), FTA_Responses!$A:$A, "<" & EOMONTH(DATE(YEAR($A54), MONTH($A54), 1), 0) + 1 ) -> 0
A55: =EDATE(A54,1) -> 46113 | B55: =COUNTIFS( FTA_Responses!$A:$A, ">=" & DATE(YEAR($A55), MONTH($A55), 1), FTA_Responses!$A:$A, "<" & EOMONTH(DATE(YEAR($A55), MONTH($A55), 1), 0) + 1 ) -> 0
A56: =EDATE(A55,1) -> 46143 | B56: =COUNTIFS( FTA_Responses!$A:$A, ">=" & DATE(YEAR($A56), MONTH($A56), 1), FTA_Responses!$A:$A, "<" & EOMONTH(DATE(YEAR($A56), MONTH($A56), 1), 0) + 1 ) -> 0
...

Sheet FTA Source Analysis Table
A1: FTA Source Analysis Table.
A2: SOURCE | B2: COUNT | C2: % of TOTAL
A3: A friend | B3: =COUNTIF(FTA_Responses!K:K,"A friend") -> 24 | C3: =B3 / COUNTA(FTA_Responses!O:O) -> 0.61538462
A4: A worker in the church | B4: =COUNTIF(FTA_Responses!K:K,"A worker in the church") -> 4 | C4: =B4 / COUNTA(FTA_Responses!O:O) -> 0.1025641
A5: Church member | B5: =COUNTIF(FTA_Responses!K:K,"Church member") -> 3 | C5: =B5 / COUNTA(FTA_Responses!O:O) -> 0.076923077
A6: Colleague | B6: =COUNTIF(FTA_Responses!K:K,"Colleague") -> 3 | C6: =B6 / COUNTA(FTA_Responses!O:O) -> 0.076923077
A7: Spouse | B7: =COUNTIF(FTA_Responses!K:K,"Spouse") -> 1 | C7: =B7 / COUNTA(FTA_Responses!O:O) -> 0.025641026
A8: Self (Social Media) | B8: =COUNTIF(FTA_Responses!K:K,"Self(Social Media)") -> 1 | C8: =B8 / COUNTA(FTA_Responses!O:O) -> 0.025641026
A9: Self (Billboard) | B9: =COUNTIF(FTA_Responses!K:K,"Self(Billboard)") -> 1 | C9: =B9 / COUNTA(FTA_Responses!O:O) -> 0.025641026
A10: Home cell | B10: =COUNTIF(FTA_Responses!K:K,"Home cell") -> 0 | C10: =B10 / COUNTA(FTA_Responses!O:O) -> 0
A11: Other | B11: =COUNTIF(FTA_Responses!K:K,"Other") -> 1 | C11: =B11 / COUNTA(FTA_Responses!O:O) -> 0.025641026

Sheet Dashboard_Metrics(Metric formul
A1: Total FTAs (All-time) | B1: FTAs This Month | C1: FTAs This Week | D1: FTAs Today | E1: Average Overall Experience Rating | F1: Average Worship Rating | G1: Average Word Rating | H1: Membership Interest Rate (%) | I1: Follow-up Completion Rate (%)
A2: 38 | B2: 13 | C2: 0 | D2: 0 | E2: 4.24 | F2: 4.11 | G2: 4.13 | H2: 31.58 | I2: 92.31

Sheet Data_Quality
A1: METRIC | B1: VALUE
A2: Total FTA Responses | B2: =COUNTA(FTA_Responses!A:A)-1 -> 38
A3: FTAs Missing FTA_ID | B3: =COUNTIFS( FTA_Responses!A2:A1000,"<>", FTA_Responses!O2:O1000,"" ) -> 0
A4: FTAs Missing Timestamp | B4: =COUNTIFS( FTA_Responses!O2:O1000,"<>", FTA_Responses!A2:A1000,"" ) -> 0
A5: Assignments Without Team Member | B5: =COUNTIFS( Assignment_Log!A2:A1000,"<>", Assignment_Log!F2:F1000,"" ) -> 0
A6: Assignments without Status | B6: =COUNTIFS( Assignment_Log!A2:A1000,"<>", Assignment_Log!H2:H1000,"" ) -> 0
A7: Feedback Without FTA_ID | B7: =COUNTIFS( Feedback_Responses!A2:A1000,"<>", Feedback_Responses!B2:B1000,"" ) -> 0
